2021-12-29 03:57:58,193 INFO    MainThread:2332 [internal.py:wandb_internal():90] W&B internal server running at pid: 2332, started at: 2021-12-29 03:57:58.190223
2021-12-29 03:57:58,195 INFO    WriterThread:2332 [datastore.py:open_for_write():77] open: /content/drive/MyDrive/Colab Notebooks/stylegan2-pytorch/wandb/run-20211229_035757-cxeenjh9/run-cxeenjh9.wandb
2021-12-29 03:57:58,196 DEBUG   HandlerThread:2332 [handler.py:handle_request():130] handle_request: check_version
2021-12-29 03:57:58,200 DEBUG   SenderThread:2332 [sender.py:send():234] send: header
2021-12-29 03:57:58,200 DEBUG   SenderThread:2332 [sender.py:send_request():248] send_request: check_version
2021-12-29 03:57:58,249 DEBUG   SenderThread:2332 [sender.py:send():234] send: run
2021-12-29 03:57:58,255 INFO    SenderThread:2332 [sender.py:_maybe_setup_resume():485] checking resume status for crobbins327/KID_512-StyleGANv2-ADA/cxeenjh9
2021-12-29 03:57:58,541 ERROR   SenderThread:2332 [internal_api.py:execute():144] 409 response executing GraphQL.
2021-12-29 03:57:58,541 ERROR   SenderThread:2332 [internal_api.py:execute():145] {"errors":[{"message":"Error 1062: Duplicate entry '621526-cxeenjh9' for key 'PRIMARY'","path":["upsertBucket"]}],"data":{"upsertBucket":null}}
2021-12-29 03:57:59,250 INFO    WriterThread:2332 [datastore.py:close():281] close: /content/drive/MyDrive/Colab Notebooks/stylegan2-pytorch/wandb/run-20211229_035757-cxeenjh9/run-cxeenjh9.wandb
2021-12-29 03:57:59,250 INFO    HandlerThread:2332 [handler.py:finish():731] shutting down handler
2021-12-29 03:57:59,251 ERROR   MainThread:2332 [internal.py:wandb_internal():158] Thread SenderThread:
Traceback (most recent call last):
  File "/usr/local/lib/python3.7/dist-packages/wandb/apis/normalize.py", line 24, in wrapper
    return func(*args, **kwargs)
  File "/usr/local/lib/python3.7/dist-packages/wandb/sdk/internal/internal_api.py", line 1298, in upsert_run
    response = self.gql(mutation, variable_values=variable_values, **kwargs)
  File "/usr/local/lib/python3.7/dist-packages/wandb/sdk/lib/retry.py", line 102, in __call__
    result = self._call_fn(*args, **kwargs)
  File "/usr/local/lib/python3.7/dist-packages/wandb/sdk/internal/internal_api.py", line 147, in execute
    six.reraise(*sys.exc_info())
  File "/usr/local/lib/python3.7/dist-packages/six.py", line 703, in reraise
    raise value
  File "/usr/local/lib/python3.7/dist-packages/wandb/sdk/internal/internal_api.py", line 141, in execute
    return self.client.execute(*args, **kwargs)
  File "/usr/local/lib/python3.7/dist-packages/wandb/vendor/gql-0.2.0/gql/client.py", line 52, in execute
    result = self._get_result(document, *args, **kwargs)
  File "/usr/local/lib/python3.7/dist-packages/wandb/vendor/gql-0.2.0/gql/client.py", line 60, in _get_result
    return self.transport.execute(document, *args, **kwargs)
  File "/usr/local/lib/python3.7/dist-packages/wandb/vendor/gql-0.2.0/gql/transport/requests.py", line 39, in execute
    request.raise_for_status()
  File "/usr/local/lib/python3.7/dist-packages/requests/models.py", line 941, in raise_for_status
    raise HTTPError(http_error_msg, response=self)
requests.exceptions.HTTPError: 409 Client Error: Conflict for url: https://api.wandb.ai/graphql

During handling of the above exception, another exception occurred:

Traceback (most recent call last):
  File "/usr/local/lib/python3.7/dist-packages/wandb/sdk/internal/internal_util.py", line 52, in run
    self._run()
  File "/usr/local/lib/python3.7/dist-packages/wandb/sdk/internal/internal_util.py", line 102, in _run
    self._process(record)
  File "/usr/local/lib/python3.7/dist-packages/wandb/sdk/internal/internal.py", line 291, in _process
    self._sm.send(record)
  File "/usr/local/lib/python3.7/dist-packages/wandb/sdk/internal/sender.py", line 236, in send
    send_handler(record)
  File "/usr/local/lib/python3.7/dist-packages/wandb/sdk/internal/sender.py", line 687, in send_run
    self._init_run(run, config_value_dict)
  File "/usr/local/lib/python3.7/dist-packages/wandb/sdk/internal/sender.py", line 725, in _init_run
    commit=run.git.last_commit or None,
  File "/usr/local/lib/python3.7/dist-packages/wandb/apis/normalize.py", line 26, in wrapper
    raise CommError(err.response, err)
wandb.errors.CommError: <Response [409]>
2021-12-29 03:58:01,265 INFO    MainThread:2332 [internal.py:handle_exit():77] Internal process exited
